Invalid HTTP_HOST header: 'localhost'. You may need to add 'localhost' to ALLOWED_HOSTS.
Traceback (most recent call last):
  File "/usr/local/lib/python3.9/site-packages/django/core/handlers/exception.py", line 55, in inner
    response = get_response(request)
  File "/usr/local/lib/python3.9/site-packages/django/utils/deprecation.py", line 133, in __call__
    response = self.process_request(request)
  File "/usr/local/lib/python3.9/site-packages/django/middleware/common.py", line 48, in process_request
    host = request.get_host()
  File "/usr/local/lib/python3.9/site-packages/django/http/request.py", line 150, in get_host
    raise DisallowedHost(msg)
django.core.exceptions.DisallowedHost: Invalid HTTP_HOST header: 'localhost'. You may need to add 'localhost' to ALLOWED_HOSTS.
Invalid HTTP_HOST header: 'localhost'. You may need to add 'localhost' to ALLOWED_HOSTS.
Traceback (most recent call last):
  File "/usr/local/lib/python3.9/site-packages/django/core/handlers/exception.py", line 55, in inner
    response = get_response(request)
  File "/usr/local/lib/python3.9/site-packages/django/utils/deprecation.py", line 133, in __call__
    response = self.process_request(request)
  File "/usr/local/lib/python3.9/site-packages/django/middleware/common.py", line 48, in process_request
    host = request.get_host()
  File "/usr/local/lib/python3.9/site-packages/django/http/request.py", line 150, in get_host
    raise DisallowedHost(msg)
django.core.exceptions.DisallowedHost: Invalid HTTP_HOST header: 'localhost'. You may need to add 'localhost' to ALLOWED_HOSTS.
Invalid HTTP_HOST header: 'localhost'. You may need to add 'localhost' to ALLOWED_HOSTS.
Traceback (most recent call last):
  File "/usr/local/lib/python3.9/site-packages/django/core/handlers/exception.py", line 55, in inner
    response = get_response(request)
  File "/usr/local/lib/python3.9/site-packages/django/utils/deprecation.py", line 133, in __call__
    response = self.process_request(request)
  File "/usr/local/lib/python3.9/site-packages/django/middleware/common.py", line 48, in process_request
    host = request.get_host()
  File "/usr/local/lib/python3.9/site-packages/django/http/request.py", line 150, in get_host
    raise DisallowedHost(msg)
django.core.exceptions.DisallowedHost: Invalid HTTP_HOST header: 'localhost'. You may need to add 'localhost' to ALLOWED_HOSTS.
Invalid HTTP_HOST header: 'localhost'. You may need to add 'localhost' to ALLOWED_HOSTS.
Traceback (most recent call last):
  File "/usr/local/lib/python3.9/site-packages/django/core/handlers/exception.py", line 55, in inner
    response = get_response(request)
  File "/usr/local/lib/python3.9/site-packages/django/utils/deprecation.py", line 133, in __call__
    response = self.process_request(request)
  File "/usr/local/lib/python3.9/site-packages/django/middleware/common.py", line 48, in process_request
    host = request.get_host()
  File "/usr/local/lib/python3.9/site-packages/django/http/request.py", line 150, in get_host
    raise DisallowedHost(msg)
django.core.exceptions.DisallowedHost: Invalid HTTP_HOST header: 'localhost'. You may need to add 'localhost' to ALLOWED_HOSTS.
Invalid HTTP_HOST header: 'localhost'. You may need to add 'localhost' to ALLOWED_HOSTS.
Traceback (most recent call last):
  File "/usr/local/lib/python3.9/site-packages/django/core/handlers/exception.py", line 55, in inner
    response = get_response(request)
  File "/usr/local/lib/python3.9/site-packages/django/utils/deprecation.py", line 133, in __call__
    response = self.process_request(request)
  File "/usr/local/lib/python3.9/site-packages/django/middleware/common.py", line 48, in process_request
    host = request.get_host()
  File "/usr/local/lib/python3.9/site-packages/django/http/request.py", line 150, in get_host
    raise DisallowedHost(msg)
django.core.exceptions.DisallowedHost: Invalid HTTP_HOST header: 'localhost'. You may need to add 'localhost' to ALLOWED_HOSTS.
Invalid HTTP_HOST header: 'localhost'. You may need to add 'localhost' to ALLOWED_HOSTS.
Traceback (most recent call last):
  File "/usr/local/lib/python3.9/site-packages/django/core/handlers/exception.py", line 55, in inner
    response = get_response(request)
  File "/usr/local/lib/python3.9/site-packages/django/utils/deprecation.py", line 133, in __call__
    response = self.process_request(request)
  File "/usr/local/lib/python3.9/site-packages/django/middleware/common.py", line 48, in process_request
    host = request.get_host()
  File "/usr/local/lib/python3.9/site-packages/django/http/request.py", line 150, in get_host
    raise DisallowedHost(msg)
django.core.exceptions.DisallowedHost: Invalid HTTP_HOST header: 'localhost'. You may need to add 'localhost' to ALLOWED_HOSTS.
Invalid HTTP_HOST header: 'localhost'. You may need to add 'localhost' to ALLOWED_HOSTS.
Traceback (most recent call last):
  File "/usr/local/lib/python3.9/site-packages/django/core/handlers/exception.py", line 55, in inner
    response = get_response(request)
  File "/usr/local/lib/python3.9/site-packages/django/utils/deprecation.py", line 133, in __call__
    response = self.process_request(request)
  File "/usr/local/lib/python3.9/site-packages/django/middleware/common.py", line 48, in process_request
    host = request.get_host()
  File "/usr/local/lib/python3.9/site-packages/django/http/request.py", line 150, in get_host
    raise DisallowedHost(msg)
django.core.exceptions.DisallowedHost: Invalid HTTP_HOST header: 'localhost'. You may need to add 'localhost' to ALLOWED_HOSTS.
Invalid HTTP_HOST header: 'localhost'. You may need to add 'localhost' to ALLOWED_HOSTS.
Traceback (most recent call last):
  File "/usr/local/lib/python3.9/site-packages/django/core/handlers/exception.py", line 55, in inner
    response = get_response(request)
  File "/usr/local/lib/python3.9/site-packages/django/utils/deprecation.py", line 133, in __call__
    response = self.process_request(request)
  File "/usr/local/lib/python3.9/site-packages/django/middleware/common.py", line 48, in process_request
    host = request.get_host()
  File "/usr/local/lib/python3.9/site-packages/django/http/request.py", line 150, in get_host
    raise DisallowedHost(msg)
django.core.exceptions.DisallowedHost: Invalid HTTP_HOST header: 'localhost'. You may need to add 'localhost' to ALLOWED_HOSTS.
Invalid HTTP_HOST header: 'localhost'. You may need to add 'localhost' to ALLOWED_HOSTS.
Traceback (most recent call last):
  File "/usr/local/lib/python3.9/site-packages/django/core/handlers/exception.py", line 55, in inner
    response = get_response(request)
  File "/usr/local/lib/python3.9/site-packages/django/utils/deprecation.py", line 133, in __call__
    response = self.process_request(request)
  File "/usr/local/lib/python3.9/site-packages/django/middleware/common.py", line 48, in process_request
    host = request.get_host()
  File "/usr/local/lib/python3.9/site-packages/django/http/request.py", line 150, in get_host
    raise DisallowedHost(msg)
django.core.exceptions.DisallowedHost: Invalid HTTP_HOST header: 'localhost'. You may need to add 'localhost' to ALLOWED_HOSTS.
Invalid HTTP_HOST header: 'localhost'. You may need to add 'localhost' to ALLOWED_HOSTS.
Traceback (most recent call last):
  File "/usr/local/lib/python3.9/site-packages/django/core/handlers/exception.py", line 55, in inner
    response = get_response(request)
  File "/usr/local/lib/python3.9/site-packages/django/utils/deprecation.py", line 133, in __call__
    response = self.process_request(request)
  File "/usr/local/lib/python3.9/site-packages/django/middleware/common.py", line 48, in process_request
    host = request.get_host()
  File "/usr/local/lib/python3.9/site-packages/django/http/request.py", line 150, in get_host
    raise DisallowedHost(msg)
django.core.exceptions.DisallowedHost: Invalid HTTP_HOST header: 'localhost'. You may need to add 'localhost' to ALLOWED_HOSTS.
Internal Server Error: /access_denied
Traceback (most recent call last):
  File "/usr/local/lib/python3.9/site-packages/django/core/handlers/exception.py", line 55, in inner
    response = get_response(request)
  File "/usr/local/lib/python3.9/site-packages/django/core/handlers/base.py", line 197, in _get_response
    response = wrapped_callback(request, *callback_args, **callback_kwargs)
  File "/app/home/views.py", line 27, in access_denied
    return render(request, 'access_denied.html', {})
  File "/usr/local/lib/python3.9/site-packages/django/shortcuts.py", line 24, in render
    content = loader.render_to_string(template_name, context, request, using=using)
  File "/usr/local/lib/python3.9/site-packages/django/template/loader.py", line 62, in render_to_string
    return template.render(context, request)
  File "/usr/local/lib/python3.9/site-packages/django/template/backends/django.py", line 61, in render
    return self.template.render(context)
  File "/usr/local/lib/python3.9/site-packages/django/template/base.py", line 175, in render
    return self._render(context)
  File "/usr/local/lib/python3.9/site-packages/django/test/utils.py", line 112, in instrumented_test_render
    return self.nodelist.render(context)
  File "/usr/local/lib/python3.9/site-packages/django/template/base.py", line 1005, in render
    return SafeString("".join([node.render_annotated(context) for node in self]))
  File "/usr/local/lib/python3.9/site-packages/django/template/base.py", line 1005, in <listcomp>
    return SafeString("".join([node.render_annotated(context) for node in self]))
  File "/usr/local/lib/python3.9/site-packages/django/template/base.py", line 966, in render_annotated
    return self.render(context)
  File "/usr/local/lib/python3.9/site-packages/django/template/loader_tags.py", line 157, in render
    return compiled_parent._render(context)
  File "/usr/local/lib/python3.9/site-packages/django/test/utils.py", line 112, in instrumented_test_render
    return self.nodelist.render(context)
  File "/usr/local/lib/python3.9/site-packages/django/template/base.py", line 1005, in render
    return SafeString("".join([node.render_annotated(context) for node in self]))
  File "/usr/local/lib/python3.9/site-packages/django/template/base.py", line 1005, in <listcomp>
    return SafeString("".join([node.render_annotated(context) for node in self]))
  File "/usr/local/lib/python3.9/site-packages/django/template/base.py", line 966, in render_annotated
    return self.render(context)
  File "/usr/local/lib/python3.9/site-packages/django/template/loader_tags.py", line 208, in render
    return template.render(context)
  File "/usr/local/lib/python3.9/site-packages/django/template/base.py", line 177, in render
    return self._render(context)
  File "/usr/local/lib/python3.9/site-packages/django/test/utils.py", line 112, in instrumented_test_render
    return self.nodelist.render(context)
  File "/usr/local/lib/python3.9/site-packages/django/template/base.py", line 1005, in render
    return SafeString("".join([node.render_annotated(context) for node in self]))
  File "/usr/local/lib/python3.9/site-packages/django/template/base.py", line 1005, in <listcomp>
    return SafeString("".join([node.render_annotated(context) for node in self]))
  File "/usr/local/lib/python3.9/site-packages/django/template/base.py", line 966, in render_annotated
    return self.render(context)
  File "/usr/local/lib/python3.9/site-packages/django/template/defaulttags.py", line 314, in render
    match = condition.eval(context)
  File "/usr/local/lib/python3.9/site-packages/django/template/defaulttags.py", line 877, in eval
    return self.value.resolve(context, ignore_failures=True)
  File "/usr/local/lib/python3.9/site-packages/django/template/base.py", line 742, in resolve
    new_obj = func(obj, *arg_vals)
  File "/app/home/templatetags/group_tags.py", line 9, in has_group
    group = Group.objects.get(name=group_name)
  File "/usr/local/lib/python3.9/site-packages/django/db/models/manager.py", line 87, in manager_method
    return getattr(self.get_queryset(), name)(*args, **kwargs)
  File "/usr/local/lib/python3.9/site-packages/django/db/models/query.py", line 637, in get
    raise self.model.DoesNotExist(
django.contrib.auth.models.Group.DoesNotExist: Group matching query does not exist.
